Workbook

Sheet Raw material
C2: Crystal Forte | D2: Crystal Clear | E2: Crystal Gain | F2: Crystal De-lime | G2: Crystal Dip | H2: Crystal Degreaser EX | I2: Crystal Grill | J2: Crystal Silver | K2: Crystal Stainless | L2: Crystal Decho | M2: Crystal Drain | N2: Crystal Quat | O2: Crystal Bright | P2: Crystal Sani Gain | Q2: Crystal Surfaces | R2: Crystal Sanidet | S2: Crystal lime | T2: Crystal Alcosan | U2: Magic light | V2: Magic Neutral | W2: Safe Boost | X2: Safe Alkazol | Y2: Safe oilgo | Z2: Safe Essential | AA2: Safe Complete | AB2: Safe color | AC2: Safe Bleach | AD2: Safe Oxygen | AE2: Safe white | AF2: Safe Sour | AG2: Safe Prime | AH2: Safe Rust | AI2: Safe Actifos | AJ2: Safe Oilaway | AK2: Safe Iron Blaster | AL2: Safe Echo Forte | AM2: Safe Force | AN2: Safe Intense new | AO2: Safe Neutra Soft | AP2: Safe Advance | AQ2: Safe Echo | AR2: Safe breeze | AS2: Safe All | AT2: Safe Starch | AU2: Touch Handbac | AV2: Touch foam | AW2: Touch Botanic Shampoo and Body 2x5 | AX2: Touch Botanic H&B Head and Body 12x500 ml | AY2: Touch Botanic Hand & Face | AZ2: Touch Peach | BA2: Touch Adams | BB2: Touch Soft | BC2: Touch Botanic | BD2: Touch Alcodis | BE2: Touch lavander hand and face | BF2: Touch lavender shampoo and body | BG2: Touch pearl | BH2: Touch Foam Bac | BI2: Care Alco Gel | BJ2: Care Alcodis | BK2: Care Sani Gel | BL2: Speed Toilet S1 | BM2: Speed Toilet S1 Conc | BN2: Speed Multi S2 | BO2: Speed Multi S2 Conc | BP2: Speed Glass S3 | BQ2: Speed Glass S3 Conc | BR2: Speed Furniture S4 | BS2: Speed Fresh S5 | BT2: Speed Fresh S5 Conc | BU2: Speed Flush S6 | BV2: Speed Scouring S7 | BW2: Speed Ketle S8 | BX2: Speed Hygenic breeze | BY2: way extract | BZ2: way foam | CA2: way lime | CB2: Way Force | CC2: way auto best | CD2: way best | CE2: way strip | CF2: way polish | CG2: Fabic NL 556 | CH2: Fabic CL 139T | CI2: Fabic KL574F | CJ2: Fabic DL144Q | CK2: Total
A3: Itemcode | B3: Trade Name | C3: 0 | D3: 3 | E3: 5 | F3: 2 | G3: 1 | H3: 1 | I3: 4 | K3: 0.5 | L3: 1 | M3: 3 | N3: 1 | P3: 1 | V3: 1 | X3: 1 | AA3: 2 | AB3: 0 | AD3: 3 | AE3: 1 | AG3: 1 | AI3: 1 | AJ3: 1 | AN3: 1 | AU3: 1 | AY3: 0.5 | AZ3: 1 | BJ3: 1 | BP3: 0.5 | BR3: 0.5 | BS3: 0.5 | BU3: 0.5 | BV3: 1 | BX3: 2 | BY3: 0.5 | CA3: 1 | CB3: 1 | CG3: 1 | CH3: 3 | CJ3: 0.12
A4: ERM00003 | B4: DYE BLUE (CI 42051) (Acid Blue 3) | D4: =0.02*D3 -> 0.06 | Q4: =Q3*0.005 -> 0 | AY4: =AY3*0.0015 -> 0.00075 | BA4: =BA3*0.004 -> 0 | BG4: =BG3*0.004 -> 0 | BP4: =0.0036*BP3 -> 0.0018 | BQ4: =BQ3*0.0144 -> 0 | BX4: =0.018*BX3 -> 0.036 | CK4: =SUM(C4:CJ4) -> 0.09855
A5: ERM00004 | B5: LUTENSOL A07 / GALAXY MW257 | J5: =J3*20 -> 0 | Y5: =Y3*525 -> 0 | Z5: =Z3*202.5 -> 0 | AJ5: =640*AJ3 -> 640 | AP5: =AP3*47.1 -> 0 | BR5: =BR3*20 -> 10 | CE5: =CE3*17 -> 0 | CK5: =SUM(C5:CJ5) -> 650
A6: ERM00005 | B6: DYE BLUE (CI 61585) (Acid Blue 80) | P6: =P3*0.06 -> 0.06 | BL6: =BL3*0.08 -> 0 | BM6: =BM3*0.32 -> 0 | BN6: =BN3*0.028 -> 0 | BO6: =BO3*0.112 -> 0 | BU6: =BU3*0.2 -> 0.1 | CC6: =CC3*0.0056 -> 0 | CK6: =SUM(C6:CJ6) -> 0.16
A7: ERM00007 | B7: DYE BLUE (CI 42090) (Acid Blue 9) (40%) | AO7: =AO3*0.017 -> 0 | BE7: =BE3*0.003 -> 0 | BF7: =BF3*0.003 -> 0 | CK7: =SUM(C7:CJ7) -> 0
A8: ERM00008 | B8: LUTENSOL A03 - GALAXY MW 253 | Y8: =Y3*105 -> 0 | Z8: =Z3*67.5 -> 0 | BN8: =BN3*5 -> 0 | BO8: =BO3*20 -> 0 | CK8: =SUM(C8:CJ8) -> 0
A9: ERM00009 | B9: MONOTROP 1620 | H9: =H3*20 -> 20 | I9: =40*I3 -> 160 | CK9: =SUM(C9:CJ9) -> 180
A10: ERM00010 | B10: DYE YELLOW (CI 19140) (Acid Yellow 23) | E10: =E3*0.06 -> 0.3 | P10: =P3*0.2 -> 0.2 | Q10: =Q3*0.04 -> 0 | U10: =0.06*U3 -> 0 | AY10: =AY3*0.004 -> 0.002 | BN10: =BN3*0.02 -> 0 | BO10: =BO3*0.08 -> 0 | CG10: =CG3*0.06 -> 0.06 | CK10: =SUM(C10:CJ10) -> 0.562
A11: ERM00013 | B11: GENAPOL BE 2810 - DEHYPON LT 104 | M11: =11*M3 -> 33 | CK11: =SUM(C11:CJ11) -> 33
A12: ERM00014 | B12: LUTENSOL TO129 | Q12: =Q3*45 -> 0 | AM12: =AM3*30 -> 0 | CB12: =CB3*54 -> 54 | CK12: =SUM(C12:CJ12) -> 54
A13: ERM00015 | B13: LUTENSOL TO8 | P13: =P3*110 -> 110 | Q13: =Q3*120 -> 0 | R13: =R3*120 -> 0 | BN13: =BN3*20 -> 0 | BO13: =BO3*80 -> 0 | BX13: =80*BX3 -> 160 | CA13: =60*CA3 -> 60 | CC13: =CC3*60 -> 0 | CK13: =SUM(C13:CJ13) -> 330
A14: ERM00017 | B14: PLURAFAC LF221 - 100% - DOWFAX 20B102 | D14: =114.24*D3 -> 342.72 | F14: =8*F3 -> 16 | S14: =8*S3 -> 0 | BW14: =BW3*4 -> 0 | BY14: =BY3*128 -> 64 | CC14: =CC3*60 -> 0 | CK14: =SUM(C14:CJ14) -> 422.72
A15: ERM00018 | B15: EMPIGEN BSF/A | V15: =V3*40 -> 40 | AN15: =160*AN3 -> 160 | AW15: =AW3*190 -> 0 | AX15: =AX3*190 -> 0 | AY15: =AY3*80 -> 40 | AZ15: =AZ3*32 -> 32 | BA15: =BA3*190 -> 0 | BB15: =BB3*80 -> 0 | BC15: =190*BC3 -> 0 | BE15: =BE3*80 -> 0 | BF15: =BF3*190 -> 0 | CK15: =SUM(C15:CJ15) -> 272
A16: ERM00019 | B16: EMPIGEN BAC 50 - BTC 50% | R16: =R3*280 -> 0 | BD16: =BD3*4 -> 0 | BN16: =BN3*19.6 -> 0 | BO16: =BO3*78.4 -> 0 | CK16: =SUM(C16:CJ16) -> 0
A17: ERM00020 | B17: NANSA SSA/U - MARLON AS3 | E17: =E3*80 -> 400 | H17: =H3*26 -> 26 | P17: =P3*205.8 -> 205.8 | Q17: =Q3*25 -> 0 | U17: =120*U3 -> 0 | V17: =V3*60 -> 60 | Z17: =Z3*21 -> 0 | AM17: =AM3*120 -> 0 | AP17: =AP3*151.5 -> 0 | BV17: =BV3*40 -> 40 | CB17: =CB3*120 -> 120 | CG17: =CG3*129.4 -> 129.4 | CK17: =SUM(C17:CJ17) -> 981.2
A18: ERM00021 | B18: BAYHIBIT AM - SEQUEST 700A - CUBLEN P50 - CONNECT PBTC | W18: =W3*20 -> 0 | AC18: =AC3*10 -> 0 | CK18: =SUM(C18:CJ18) -> 0
A19: ERM00023 | B19: ELTESOL SC40 - STEPANATE SCS 40 | D19: =30*D3 -> 90 | CC19: =CC3*10 -> 0 | CI19: =CI3*108 -> 0 | CK19: =SUM(C19:CJ19) -> 90
A20: ERM00024 | B20: SILICONE EMULSION - LE 46 - RHODOSIL E1P | BR20: =BR3*200 -> 100 | CK20: =SUM(C20:CJ20) -> 100
A21: ERM00025 | B21: PRIFAC 7908 - PALMERA B1220 - EDENOR PK 12-18 GA | CK21: =SUM(C21:CJ21) -> 0
A22: ERM00027 | B22: EMPIGEN OB/EB - AMMONYX LO | CI22: =CI3*92 -> 0 | CK22: =SUM(C22:CJ22) -> 0
A23: ERM00028 | B23: TINOPAL CBS-X - CF-351 | Y23: =Y3*4.5 -> 0 | Z23: =Z3*13.5 -> 0 | AJ23: =4.4*AJ3 -> 4.4 | AM23: =AM3*4 -> 0 | AN23: =6*AN3 -> 6 | AP23: =AP3*1.3 -> 0 | CK23: =SUM(C23:CJ23) -> 10.4
A24: ERM00029 | B24: PERFUME AR 621591 ALDEHYDE COMPOUND SPR MLT LPV - OZONIC MULTI - (GC2465) | AA24: =1.25*AA3 -> 2.5 | AL24: =AL3*1.25 -> 0 | AP24: =AP3*6.14 -> 0 | BY24: =BY3*12 -> 6 | BZ24: =BZ3*10 -> 0 | CC24: =CC3*3 -> 0 | CD24: =CD3*2 -> 0 | CK24: =SUM(C24:CJ24) -> 8.5
A25: ERM00030 | B25: GENAMINE CS302D - ARMEEN 2MCD - EMBIGEN AB/E - NORAM DMCD | CK25: =SUM(C25:CJ25) -> 0
A26: ERM00031 | B26: STEPANTEX VK 90 - NOXAMIUM 920A - CAFLON EQ90 / eterol 100 | AG26: =AG3*40 -> 40 | AO26: =AO3*40 -> 0 | AR26: =AR3*40 -> 0 | CK26: =SUM(C26:CJ26) -> 40
A27: ERM00032 | B27: MAGNESIUM SULPHATE 7H20- EPSOM | G27: =G3*10 -> 10 | AB27: =AB3*10 -> 0 | CG27: =CG3*40 -> 40 | CK27: =SUM(C27:CJ27) -> 50
A28: ERM00033 | B28: DOWANOL DPM - SOLVENON DPM - ARCOSOLV DPM | I28: =80*I3 -> 320 | K28: =K3*(10*2) -> 10 | BP28: =20*BP3 -> 10 | BQ28: =BQ3*80 -> 0 | BR28: =BR3*40 -> 20 | CK28: =SUM(C28:CJ28) -> 360
A29: ERM00034 | B29: 2-ETHYL HEXANOIC ACID | CK29: =SUM(C29:CJ29) -> 0
A30: ERM00035 | B30: TRILON M LIQUID | H30: =H3*46 -> 46 | CK30: =SUM(C30:CJ30) -> 46
A31: ERM00039 | B31: ADDITIVE CL11 - SILWET L-7002 - SP3300 | CK31: =SUM(C31:CJ31) -> 0
A32: ERM00040 | B32: ACCUSOL 445 - SOKALAN PA 25 | W32: =W3*40 -> 0 | BV32: =BV3*2 -> 2 | CK32: =SUM(C32:CJ32) -> 2
A33: ERM00043 | B33: CITRIC ACID MONO | D33: =1.2*D3 -> 3.6 | E33: =E3*2 -> 10 | J33: =58*J3 -> 0 | R33: =R3*100 -> 0 | U33: =2*U3 -> 0 | V33: =V3*2 -> 2 | Y33: =Y3*7.5 -> 0 | AH33: =AH3*300 -> 0 | AO33: =AO3*65.6 -> 0 | AU33: =AU3*1.6 -> 1.6 | AV33: =AV3*1.6 -> 0 | AW33: =AW3*2 -> 0 | AX33: =AX3*2 -> 0 | AY33: =AY3*1.6 -> 0.8 | AZ33: =AZ3*2 -> 2 | BA33: =BA3*2 -> 0 | BB33: =BB3*1.6 -> 0 | BC33: =2*BC3 -> 0 | BE33: =BE3*1.6 -> 0 | BF33: =BF3*2 -> 0 | BG33: =BG3*1.6 -> 0 | BH33: =BH3*1.6 -> 0 | BL33: =BL3*80 -> 0 | BM33: =BM3*320 -> 0 | BN33: =BN3*6.5 -> 0 | BO33: =BO3*26 -> 0 | CC33: =CC3*1.6 -> 0 | CG33: =CG3*4.6 -> 4.6 | CK33: =SUM(C33:CJ33) -> 24.6
A34: ERM00049 | B34: POTASSIUM SORBATE | D34: =4*D3 -> 12 | CK34: =SUM(C34:CJ34) -> 12
A35: ERM00053 | B35: TRILON B87% | C35: =C3*60 -> 0 | Q35: =Q3*50 -> 0 | T35: =T3*1 -> 0 | AM35: =AM3*43.4 -> 0 | CB35: =CB3*41 -> 41 | CE35: =CE3*23 -> 0 | CK35: =SUM(C35:CJ35) -> 41
A36: ERM00056 | B36: DEQUEST 2010 - CODEX 661 - CUBLEN K60 - CONNECT HEDP | C36: =C3*12 -> 0 | AA36: =2*AA3 -> 4 | AL36: =AL3*2 -> 0 | CK36: =SUM(C36:CJ36) -> 4
A37: ERM00057 | B37: DEQUEST 2000 - CONNECT ATMP | AM37: =AM3*4 -> 0 | AN37: =20*AN3 -> 20 | CB37: =CB3*4 -> 4 | CK37: =SUM(C37:CJ37) -> 24
A38: ERM00064 | B38: DYE ORANGE (CI 15985) (Food Yellow 3) | AZ38: =AZ3*0.1 -> 0.1 | BW38: =BW3*0.1 -> 0 | CK38: =SUM(C38:CJ38) -> 0.1
A39: ERM00066 | B39: DYE YELLOW (CI 18965) (Acid Yellow 17) | CK39: =SUM(C39:CJ39) -> 0
A40: ERM00068 | B40: DYE RED (CI 45100) (Acid Red 52) | BE40: =BE3*0.0014 -> 0 | BF40: =BF3*0.0023 -> 0 | CA40: =0.006*CA3 -> 0.006 | CK40: =SUM(C40:CJ40) -> 0.006
A41: ERM00069 | B41: DYE RED (CI 16185) (Acid Red 27) | R41: =R3*0.1 -> 0 | CK41: =SUM(C41:CJ41) -> 0
...

Sheet Inventory
C1: Have | D1: Total | E1: Sub | J1: MONOTROP | K1: LUTENSOL TO8 | L1: SILICONE LE 46 | M1: PINK SPECKLES | N1: ELTESOL SX40 | O1: PER FLORAL FRESH | P1: SALICYLIC ACID | Q1: IPA | R1: HYDROGEN PEROXIDE (50%) | S1: SODUM SILICATE NA5 | T1: WHITE MINERAL OIL | U1: ProtectolGA 50 | V1: Nitric Acid 55%
A2: Itemcode | B2: Trade Name | C2: Have | D2: Total Need | E2: SOH | H2: Crystal Forte | I2: {=TRANSPOSE('Raw material'!C3:CI3)} -> 0
A3: ERM00003 | B3: DYE BLUE (CI 42051) (Acid Blue 3) | C3: 1.917 | D3: ='Raw material'!CK4 -> 0.09855 | E3: =C3-D3 -> 1.81845 | H3: Crystal Clear | I3: 3
A4: ERM00004 | B4: LUTENSOL A07 / GALAXY MW257 | C4: 2424 | D4: ='Raw material'!CK5 -> 650 | E4: =C4-D4 -> 1774 | H4: Crystal Gain | I4: 5 | AC4: No | AD4: Batch | AE4: Hold | AF4: Can do | AG4: Total | AH4: Raw Material
A5: ERM00005 | B5: DYE BLUE (CI 61585) (Acid Blue 80) | C5: 2.4 | D5: ='Raw material'!CK6 -> 0.16 | E5: =C5-D5 -> 2.24 | H5: Crystal De-lime | I5: 2 | AC5: 1 | AD5: Grill | AE5: =AF5-AG5 -> -1 | AF5: 3 | AG5: 4 | AH5: Monotrop
A6: ERM00007 | B6: DYE BLUE (CI 42090) (Acid Blue 9) (40%) | C6: 0.898 | D6: ='Raw material'!CK7 -> 0 | E6: =C6-D6 -> 0.898 | H6: Crystal Dip | I6: 1 | T6: 12 | AC6: 2 | AD6: Crystal Sani Gain | AE6: =AF6-AG6 -> -1 | AF6: 0 | AG6: 1 | AH6: LUTENSOL TO8 / Salicylic acid
A7: ERM00008 | B7: LUTENSOL A03 - GALAXY MW 253 | C7: 661 | D7: ='Raw material'!CK8 -> 0 | E7: =C7-D7 -> 661 | H7: Crystal Degreaser EX | I7: 1 | J7: 20 | AC7: 3 | AD7: Speed Hygenic breeze | AE7: =AF7-AG7 -> -1 | AF7: 1 | AG7: 2 | AH7: LUTENSOL TO8 / IPA / Per Floral Fresh
A8: ERM00009 | B8: MONOTROP 1620 | C8: 140 | D8: ='Raw material'!CK9 -> 180 | E8: =C8-D8 -> -40 | H8: Crystal Grill | I8: 4 | J8: 120 | AC8: 4 | AD8: S4 | AE8: =AF8-AG8 -> -0.5 | AF8: 0 | AG8: 0.5 | AH8: SILICONE LE 46
A9: ERM00010 | B9: DYE YELLOW (CI 19140) (Acid Yellow 23) | C9: 10.699 | D9: ='Raw material'!CK10 -> 0.562 | E9: =C9-D9 -> 10.137 | H9: Crystal Silver | AC9: 5 | AD9: Crystal Decho | AE9: =AF9-AG9 -> -1 | AF9: 0 | AG9: 1 | AH9: PINK SPECKLES
A10: ERM00013 | B10: GENAPOL BE 2810 - DEHYPON LT 104 | C10: 532.5 | D10: ='Raw material'!CK11 -> 33 | E10: =C10-D10 -> 499.5 | H10: Crystal Stainless | I10: 0.5 | AC10: 6 | AD10: way extract | AE10: =AF10-AG10 -> -0.5 | AF10: 0 | AG10: 0.5 | AH10: ELTESOL SX40
A11: ERM00014 | B11: LUTENSOL TO129 | C11: 1958 | D11: ='Raw material'!CK12 -> 54 | E11: =C11-D11 -> 1904 | H11: Crystal Decho | I11: 1 | AC11: 7 | AD11: Safe Oxygen | AE11: =AF11-AG11 -> -2 | AF11: 1 | AG11: 3 | AH11: HYDROGEN PEROXIDE (50%)
A12: ERM00015 | B12: LUTENSOL TO8 | C12: 135 | D12: ='Raw material'!CK13 -> 330 | E12: =C12-D12 -> -195 | H12: Crystal Drain | I12: 3 | AC12: 8 | AD12: Way Force | AE12: =AF12-AG12 -> 0 | AH12: SODUM SILICATE NA5 (Have 96% )
A13: ERM00017 | B13: PLURAFAC LF221 - 100% - DOWFAX 20B102 | C13: 607 | D13: ='Raw material'!CK14 -> 422.72 | E13: =C13-D13 -> 184.28 | H13: Crystal Quat | I13: 1 | AC13: 9 | AD13: Crystal Stainless | AE13: =AF13-AG13 -> -1 | AF13: 0 | AG13: 1 | AH13: WHITE MINERAL OIL
A14: ERM00018 | B14: EMPIGEN BSF/A | C14: 955 | D14: ='Raw material'!CK15 -> 272 | E14: =C14-D14 -> 683 | H14: Crystal Bright | AC14: 10 | AD14: Touch Handbac | AE14: =AF14-AG14 -> -1 | AF14: 0 | AG14: 1 | AH14: ProtectolGA 50
A15: ERM00019 | B15: EMPIGEN BAC 50 - BTC 50% | D15: ='Raw material'!CK16 -> 0 | E15: =C15-D15 -> 0 | H15: Crystal Sani Gain | I15: 1 | Q15: 6 | AC15: 11 | AD15: Fabic CL 139T | AE15: =AF15-AG15 -> -3 | AF15: 0 | AG15: 3 | AH15: Nitric Acid 55%
A16: ERM00020 | B16: NANSA SSA/U - MARLON AS3 | C16: 5000 | D16: ='Raw material'!CK17 -> 981.2 | E16: =C16-D16 -> 4018.8 | H16: Crystal Surfaces | AC16: 12 | AE16: =AF16-AG16 -> 0
A17: ERM00021 | B17: BAYHIBIT AM - SEQUEST 700A - CUBLEN P50 - CONNECT PBTC | C17: 449 | D17: ='Raw material'!CK18 -> 0 | E17: =C17-D17 -> 449 | H17: Crystal Sanidet | AC17: 13 | AE17: =AF17-AG17 -> 0
A18: ERM00023 | B18: ELTESOL SC40 - STEPANATE SCS 40 | C18: 408 | D18: ='Raw material'!CK19 -> 90 | E18: =C18-D18 -> 318 | H18: Crystal lime | AC18: 14 | AE18: =AF18-AG18 -> 0
A19: ERM00024 | B19: SILICONE EMULSION - LE 46 - RHODOSIL E1P | C19: 0 | D19: ='Raw material'!CK20 -> 100 | E19: =C19-D19 -> -100 | H19: Crystal Alcosan | AC19: 15 | AE19: =AF19-AG19 -> 0
A20: ERM00025 | B20: PRIFAC 7908 - PALMERA B1220 - EDENOR PK 12-18 GA | C20: 40 | D20: ='Raw material'!CK21 -> 0 | E20: =C20-D20 -> 40 | H20: Magic light | AC20: 16 | AE20: =AF20-AG20 -> 0
H21: Magic Neutral | I21: 1
A22: ERM00027 | B22: EMPIGEN OB/EB - AMMONYX LO | C22: 487 | D22: ='Raw material'!CK22 -> 0 | E22: =C22-D22 -> 487 | H22: Safe Boost | AC22: 17 | AE22: =AF22-AG22 -> 0
A23: ERM00028 | B23: TINOPAL CBS-X - CF-351 | C23: 162.7 | D23: ='Raw material'!CK23 -> 10.4 | E23: =C23-D23 -> 152.3 | H23: Safe Alkazol | I23: 1 | T23: 9 | AC23: 18 | AE23: =AF23-AG23 -> 0
A24: ERM00029 | B24: PERFUME AR 621591 ALDEHYDE OZONIC MULTI - (GC2465) | C24: 77.47 | D24: ='Raw material'!CK24 -> 8.5 | E24: =C24-D24 -> 68.97 | H24: Safe oilgo | AC24: 19 | AE24: =AF24-AG24 -> 0
A25: ERM00030 | B25: GENAMINE CS302D - ARMEEN 2MCD - EMBIGEN AB/E - NORAM DMCD | D25: ='Raw material'!CK25 -> 0 | E25: =C25-D25 -> 0 | H25: Safe Essential | AC25: 20 | AE25: =AF25-AG25 -> 0
A26: ERM00031 | B26: STEPANTEX VK 90 - NOXAMIUM 920A - CAFLON EQ90 / eterol 100 | C26: 565 | D26: ='Raw material'!CK26 -> 40 | E26: =C26-D26 -> 525 | H26: Safe Complete | I26: 2 | AC26: 21 | AE26: =AF26-AG26 -> 0
A27: ERM00032 | B27: MAGNESIUM SULPHATE 7H20- EPSOM | C27: 597 | D27: ='Raw material'!CK27 -> 50 | E27: =C27-D27 -> 547 | H27: Safe color | I27: 0 | AE27: =AF27-AG27 -> 0
A28: ERM00033 | B28: DOWANOL DPM - SOLVENON DPM - ARCOSOLV DPM | C28: 475 | D28: ='Raw material'!CK28 -> 360 | E28: =C28-D28 -> 115 | H28: Safe Bleach | AE28: =AF28-AG28 -> 0
A29: ERM00034 | B29: 2-ETHYL HEXANOIC ACID | D29: ='Raw material'!CK29 -> 0 | E29: =C29-D29 -> 0 | H29: Safe Oxygen | I29: 3 | R29: 2800
A30: ERM00035 | B30: TRILON M LIQUID | C30: 527 | D30: ='Raw material'!CK30 -> 46 | E30: =C30-D30 -> 481 | H30: Safe white | I30: 1 | T30: 11
A31: ERM00039 | B31: ADDITIVE CL11 - SILWET L-7002 - SP3300 | D31: ='Raw material'!CK31 -> 0 | E31: =C31-D31 -> 0 | H31: Safe Sour
A32: ERM00040 | B32: ACCUSOL 445 - SOKALAN PA 25 | C32: 258 | D32: ='Raw material'!CK32 -> 2 | E32: =C32-D32 -> 256 | H32: Safe Prime | I32: 1
A33: ERM00043 | B33: CITRIC ACID MONO | C33: 906.7 | D33: ='Raw material'!CK33 -> 24.6 | E33: =C33-D33 -> 882.1 | H33: Safe Rust | AD33: cant do it
A34: ERM00049 | B34: POTASSIUM SORBATE | C34: 27 | D34: ='Raw material'!CK34 -> 12 | E34: =C34-D34 -> 15 | H34: Safe Actifos | I34: 1 | AD34: do part of it
A35: ERM00053 | B35: TRILON B87% | C35: 983 | D35: ='Raw material'!CK35 -> 41 | E35: =C35-D35 -> 942 | H35: Safe Oilaway | I35: 1 | Q35: 270
A36: ERM00056 | B36: DEQUEST 2010 - CODEX 661 - CUBLEN K60 - CONNECT HEDP | C36: 126.6 | D36: ='Raw material'!CK36 -> 4 | E36: =C36-D36 -> 122.6 | H36: Safe Iron Blaster
A37: ERM00057 | B37: DEQUEST 2000 - CONNECT ATMP | C37: 235 | D37: ='Raw material'!CK37 -> 24 | E37: =C37-D37 -> 211 | H37: Safe Echo Forte
A38: ERM00064 | B38: DYE ORANGE (CI 15985) (Food Yellow 3) | C38: 1 | D38: ='Raw material'!CK38 -> 0.1 | E38: =C38-D38 -> 0.9 | H38: Safe Force
A39: ERM00066 | B39: DYE YELLOW (CI 18965) (Acid Yellow 17) | D39: ='Raw material'!CK39 -> 0 | E39: =C39-D39 -> 0 | H39: Safe Intense new | I39: 1
A40: ERM00068 | B40: DYE RED (CI 45100) (Acid Red 52) | C40: 0.549 | D40: ='Raw material'!CK40 -> 0.006 | E40: =C40-D40 -> 0.543 | H40: Safe Neutra Soft
...

Sheet Log
A1: Timestamp | B1: Product | C1: Batches | D1: Operator Status

Sheet Package
F1: Liquid | T1: Powder | X1: package
C2: Front Sticker | D2: Back Sticker | E2: Bottles | F2: 20 Liter Clear | G2: 20 Liter White | H2: 20 Liter Blue | I2: 4x5 Liter | J2: 2x5 Liter | K2: 1 Liter | L2: 750 ML Flat | M2: 750 ML Round | N2: 500 ML | O2: 330 ML | P2: 250 ML | Q2: 75 ML | R2: Powder | S2: 20 KG | T2: 10 KG | U2: 3 KG | V2: Carton | W2: 4x5 LTR | X2: 2x5 LTR | Y2: 10 x 1 Liter | Z2: 6x750 Round | AA2: 6x750 ML Flat | AB2: 12x500 ML | AC2: 330 ML | AD2: 250 ML | AE2: 75 ML | AF2: Capes | AG2: White Cape | AH2: Blue Cape | AI2: Red Cape | AJ2: Small white cape | AK2: Pump/Trigger | AL2: White Pump | AM2: Silver Pump | AN2: Black Pump | AO2: Trigger
A3: Crystal Forte | B3: {=TRANSPOSE('Raw material'!C3:CH3)} -> 0 | C3: =F3 -> 0 | E3: Bottles | F3: =B3*78 -> 0 | R3: Powder | V3: Carton | AF3: Capes | AK3: Pump/Trigger
A4: Crystal Clear | B4: 3 | C4: =F4 -> 297 | E4: Bottles | F4: =B4*99 -> 297 | R4: Powder | V4: Carton | AF4: Capes | AK4: Pump/Trigger
A5: Crystal Gain | B5: 5 | C5: =I5+W5 -> 2425 | E5: Bottles | I5: =W5*4 -> 1940 | R5: Powder | V5: Carton | W5: =B5*97 -> 485 | AF5: Capes | AK5: Pump/Trigger
A6: Crystal De-lime | B6: 2 | C6: =J6+X6 -> 1080 | E6: Bottles | J6: =X6*2 -> 720 | R6: Powder | V6: Carton | X6: =B6*180 -> 360 | AF6: Capes | AK6: Pump/Trigger
A7: Crystal Dip | B7: 1 | C7: =T7 -> 100 | E7: Bottles | R7: Powder | T7: =B7*100 -> 100 | V7: Carton | AF7: Capes | AK7: Pump/Trigger
A8: Crystal Degreaser EX | B8: 1 | C8: =J8+X8 -> 546 | E8: Bottles | J8: =X8*2 -> 364 | R8: Powder | V8: Carton | X8: =B8*182 -> 182 | AF8: Capes | AK8: Pump/Trigger
A9: Crystal Grill | B9: 4 | C9: =J9+X9 -> 2148 | E9: Bottles | J9: =X9*2 -> 1432 | R9: Powder | V9: Carton | X9: =B9*179 -> 716 | AF9: Capes | AK9: Pump/Trigger
A10: Crystal Silver | E10: Bottles | R10: Powder | V10: Carton | AF10: Capes | AK10: Pump/Trigger
A11: Crystal Stainless | B11: 0.5 | C11: =L11+AA11 -> 924 | D11: =L11 -> 792 | E11: Bottles | L11: =AA11*6 -> 792 | R11: Powder | V11: Carton | AA11: =B11*264 -> 132 | AF11: Capes | AK11: Pump/Trigger
A12: Crystal Decho | B12: 1 | C12: =T12 -> 100 | E12: Bottles | R12: Powder | T12: =B12*100 -> 100 | V12: Carton | AF12: Capes | AK12: Pump/Trigger
A13: Crystal Drain | B13: 3 | C13: =T13 -> 300 | E13: Bottles | R13: Powder | T13: =B13*100 -> 300 | V13: Carton | AF13: Capes | AK13: Pump/Trigger
A14: Crystal Quat | B14: 1 | C14: =J14+X14 -> 600 | E14: Bottles | J14: =X14*2 -> 400 | R14: Powder | V14: Carton | X14: =B14*200 -> 200 | AF14: Capes | AK14: Pump/Trigger
A15: Crystal Bright | C15: =U15 -> 0 | D15: =C15 -> 0 | E15: Bottles | R15: Powder | U15: =B15*333 -> 0 | V15: Carton | AF15: Capes | AK15: Pump/Trigger
A16: Crystal Sani Gain | B16: 1 | C16: =F16 -> 97 | E16: Bottles | F16: =B16*97 -> 97 | R16: Powder | V16: Carton | AF16: Capes | AK16: Pump/Trigger
A17: Crystal Surfaces | E17: Bottles | R17: Powder | V17: Carton | AF17: Capes | AK17: Pump/Trigger
A18: Crystal Sanidet | E18: Bottles | R18: Powder | V18: Carton | AF18: Capes | AK18: Pump/Trigger
A19: Crystal lime | E19: Bottles | R19: Powder | V19: Carton | AF19: Capes | AK19: Pump/Trigger
A20: Crystal Alcosan | E20: Bottles | R20: Powder | V20: Carton | AF20: Capes | AK20: Pump/Trigger
A21: Magic light | C21: =I21+W21 -> 0 | E21: Bottles | I21: =W21*4 -> 0 | R21: Powder | V21: Carton | W21: =B21*97 -> 0 | AF21: Capes | AK21: Pump/Trigger
A22: Safe Boost | B22: 1 | C22: =F22 -> 78 | E22: Bottles | F22: =B22*78 -> 78 | R22: Powder | V22: Carton | AF22: Capes | AK22: Pump/Trigger
A23: Safe Alkazol | C23: =S23 -> 0 | E23: Bottles | R23: Powder | S23: =B23*50 -> 0 | V23: Carton | AF23: Capes | AK23: Pump/Trigger
A24: Safe oilgo | B24: 1 | C24: =G24 -> 103 | E24: Bottles | G24: =B24*103 -> 103 | R24: Powder | V24: Carton | AF24: Capes | AK24: Pump/Trigger
A25: Safe Essential | C25: =G25 -> 0 | E25: Bottles | G25: =B25*100 -> 0 | R25: Powder | V25: Carton | AF25: Capes | AK25: Pump/Trigger
A26: Safe Complete | C26: =S26 -> 0 | E26: Bottles | R26: Powder | S26: =B26*50 -> 0 | V26: Carton | AF26: Capes | AK26: Pump/Trigger
A27: Safe color | B27: 2 | C27: =S27 -> 100 | E27: Bottles | R27: Powder | S27: =B27*50 -> 100 | V27: Carton | AF27: Capes | AK27: Pump/Trigger
A28: Safe Bleach | B28: 0 | C28: =H28 -> 0 | E28: Bottles | H28: =B28*85 -> 0 | R28: Powder | V28: Carton | AF28: Capes | AK28: Pump/Trigger
A29: Safe Oxygen | C29: =H29 -> 0 | E29: Bottles | H29: =B29*90 -> 0 | R29: Powder | V29: Carton | AF29: Capes | AK29: Pump/Trigger
A30: Safe white | B30: 3 | C30: =T30 -> 300 | E30: Bottles | R30: Powder | T30: =B30*100 -> 300 | V30: Carton | AF30: Capes | AK30: Pump/Trigger
A31: Safe Sour | B31: 1 | C31: =F31 -> 92 | E31: Bottles | F31: =B31*92 -> 92 | R31: Powder | V31: Carton | AF31: Capes | AK31: Pump/Trigger
A32: Safe Prime | C32: =F32 -> 0 | E32: Bottles | F32: =B32*100 -> 0 | R32: Powder | V32: Carton | AF32: Capes | AK32: Pump/Trigger
A33: Safe Rust | B33: 1 | C33: =F33 -> 89 | E33: Bottles | F33: =B33*89 -> 89 | R33: Powder | V33: Carton | AF33: Capes | AK33: Pump/Trigger
A34: Safe Actifos | C34: =G34 -> 0 | E34: Bottles | G34: =B34*106 -> 0 | R34: Powder | V34: Carton | AF34: Capes | AK34: Pump/Trigger
A35: Safe Oilaway | B35: 1 | C35: =G35 -> 106 | E35: Bottles | G35: =B35*106 -> 106 | R35: Powder | V35: Carton | AF35: Capes | AK35: Pump/Trigger
A36: Safe Iron Blaster | B36: 1 | C36: =T36 -> 100 | E36: Bottles | R36: Powder | T36: =B36*100 -> 100 | V36: Carton | AF36: Capes | AK36: Pump/Trigger
A37: Safe Echo Forte | C37: =G37 -> 0 | E37: Bottles | G37: =B37*94 -> 0 | R37: Powder | V37: Carton | AF37: Capes | AK37: Pump/Trigger
A38: Safe Force | C38: =G38 -> 0 | E38: Bottles | G38: =B38*77 -> 0 | R38: Powder | V38: Carton | AF38: Capes | AK38: Pump/Trigger
A39: Safe Intense new | C39: =G39 -> 0 | E39: Bottles | G39: =B39*77 -> 0 | R39: Powder | V39: Carton | AF39: Capes | AK39: Pump/Trigger
A40: Safe Neutra Soft | B40: 1 | E40: Bottles | R40: Powder | V40: Carton | AF40: Capes | AK40: Pump/Trigger
...

Sheet Sticker
C1: Needed | E1: Have | F1: Start | H1: Left OR Need | I1: 46387 | J1: 46026 | K1: 46027 | L1: 46028 | M1: 46030 | N1: 46033 | O1: 46034 | P1: back | Q1: 46035 | R1: Back | S1: 46036 | T1: 15-16/1 | U1: 18-19/1 | V1: back
C2: Front Sticker | D2: Back Sticker | F2: Front Sticker | G2: Back Sticker
A3: Crystal Forte | B3: {=TRANSPOSE('Raw material'!C3:CI3)} -> 0 | C3: =Package!C3 -> 0 | D3: =Package!D3 | F3: 884 | H3: =F3-C3 -> 884 | I3: =F3-163 -> 721 | S3: =I3-162 -> 559
A4: Crystal Clear | B4: 3 | C4: =Package!C4 -> 297 | D4: =Package!D4 | F4: 1590 | H4: =F4-C4 -> 1293 | L4: =F4-99 -> 1491 | T4: =L4-100 -> 1391
A5: Crystal Gain | B5: 5 | C5: =Package!C5 -> 2425 | D5: =Package!D5 | F5: 4486 | H5: =F5-C5 -> 2061 | K5: =F5-1465 -> 3021 | T5: =K5-980 -> 2041
A6: Crystal De-lime | B6: 2 | C6: =Package!C6 -> 1080 | D6: =Package!D6 | F6: 430 | H6: =F6-C6 -> -650
A7: Crystal Dip | B7: 1 | C7: =Package!C7 -> 100 | D7: =Package!D7 | F7: 618 | H7: =F7-C7 -> 518 | L7: =F7-200 -> 418
A8: Crystal Degreaser EX | B8: 1 | C8: =Package!C8 -> 546 | D8: =Package!D8 | F8: 3015 | H8: =F8-C8 -> 2469 | I8: =F8-556 -> 2459
A9: Crystal Grill | B9: 4 | C9: =Package!C9 -> 2148 | D9: =Package!D9 | F9: 2231 | H9: =F9-C9 -> 83
A10: Crystal Silver | C10: =Package!C10 | D10: =Package!D10 | F10: 1336 | H10: =F10-C10 -> 1336
A11: Crystal Stainless | B11: 0.5 | C11: =Package!C11 -> 924 | D11: =Package!D11 -> 792 | F11: 2964 | G11: 2339 | H11: =F11-C11 -> 2040
A12: Crystal Decho | B12: 1 | C12: =Package!C12 -> 100 | D12: =Package!D12 | F12: 600 | H12: =F12-C12 -> 500
A13: Crystal Drain | B13: 3 | C13: =Package!C13 -> 300 | D13: =Package!D13 | F13: 2846 | H13: =F13-C13 -> 2546 | K13: =F13-50 -> 2796 | S13: =F13-598 -> 2248
A14: Crystal Quat | B14: 1 | C14: =Package!C14 -> 600 | D14: =Package!D14 | F14: 700 | H14: =F14-C14 -> 100
A15: Crystal Bright | C15: =Package!C15 -> 0 | D15: =Package!D15 -> 0 | F15: 2680 | G15: 2704 | H15: =F15-C15 -> 2680 | O15: =F15-333 -> 2347 | P15: =G15-333 -> 2371
A16: Crystal Sani Gain | B16: 1 | C16: =Package!C16 -> 97 | D16: =Package!D16 | F16: 395 | H16: =F16-C16 -> 298
A17: Crystal Surfaces | C17: =Package!C17 | D17: =Package!D17 | F17: 2843 | H17: =F17-C17 -> 2843 | J17: =F17-450 -> 2393
A18: Crystal Sanidet | C18: =Package!C18 | D18: =Package!D18 | F18: 3938 | H18: =F18-C18 -> 3938
A19: Crystal lime | C19: =Package!C19 | D19: =Package!D19 | H19: =F19-C19 -> 0
A20: Crystal Alcosan | C20: =Package!C20 | D20: =Package!D20 | F20: 3410 | H20: =F20-C20 -> 3410
A21: Magic light | C21: =Package!C21 -> 0 | D21: =Package!D21 | F21: 232 | H21: =F21-C21 -> 232
A22: Safe Boost | B22: 1 | C22: =Package!C22 -> 78 | D22: =Package!D22 | F22: 863 | H22: =F22-C22 -> 785 | I22: =F22-81 -> 782 | T22: =I22-81 -> 701
A23: Safe Alkazol | C23: =Package!C23 -> 0 | D23: =Package!D23 | F23: 189 | H23: =F23-C23 -> 189 | Q23: =F23-100 -> 89
A24: Safe oilgo | B24: 1 | C24: =Package!C24 -> 103 | D24: =Package!D24 | F24: 530 | H24: =F24-C24 -> 427 | J24: =F24-103 -> 427
A25: Safe Essential | C25: =Package!C25 -> 0 | D25: =Package!D25 | F25: 838 | H25: =F25-C25 -> 838 | M25: =F25-101 -> 737
A26: Safe Complete | C26: =Package!C26 -> 0 | D26: =Package!D26 | F26: 409 | H26: =F26-C26 -> 409 | I26: =F26-86 -> 323
A27: Safe color | B27: 2 | C27: =Package!C27 -> 100 | D27: =Package!D27 | F27: 381 | H27: =F27-C27 -> 281 | I27: =F27-50 -> 331
A28: Safe Bleach | B28: 0 | C28: =Package!C28 -> 0 | D28: =Package!D28 | F28: 789 | H28: =F28-C28 -> 789 | K28: =F28-84 -> 705
A29: Safe Oxygen | C29: =Package!C29 -> 0 | D29: =Package!D29 | F29: 741 | H29: =F29-C29 -> 741 | K29: =F29-90 -> 651
A30: Safe white | B30: 3 | C30: =Package!C30 -> 300 | D30: =Package!D30 | F30: 3103 | H30: =F30-C30 -> 2803 | L30: =F30-100 -> 3003
A31: Safe Sour | B31: 1 | C31: =Package!C31 -> 92 | D31: =Package!D31 | F31: 303 | H31: =F31-C31 -> 211
A32: Safe Prime | C32: =Package!C32 -> 0 | D32: =Package!D32 | F32: 1388 | H32: =F32-C32 -> 1388 | Q32: =F32-100 -> 1288
A33: Safe Rust | B33: 1 | C33: =Package!C33 -> 89 | D33: =Package!D33 | F33: 1538 | H33: =F33-C33 -> 1449
A34: Safe Actifos | C34: =Package!C34 -> 0 | D34: =Package!D34 | F34: 388 | H34: =F34-C34 -> 388
A35: Safe Oilaway | B35: 1 | C35: =Package!C35 -> 106 | D35: =Package!D35 | F35: 1213 | H35: =F35-C35 -> 1107 | K35: =F35-221 -> 992
A36: Safe Iron Blaster | B36: 1 | C36: =Package!C36 -> 100 | D36: =Package!D36 | F36: 188 | H36: =F36-C36 -> 88
A37: Safe Echo Forte | C37: =Package!C37 -> 0 | D37: =Package!D37 | F37: 745 | H37: =F37-C37 -> 745
A38: Safe Force | C38: =Package!C38 -> 0 | D38: =Package!D38 | F38: 505 | H38: =F38-C38 -> 505
A39: Safe Intense new | C39: =Package!C39 -> 0 | D39: =Package!D39 | F39: 1583 | H39: =F39-C39 -> 1583
A40: Safe Neutra Soft | B40: 1 | C40: =Package!C40 | D40: =Package!D40 | H40: =F40-C40 -> 0
...
